Workbook

Sheet Aylık Rapor
B2: ="Opera " & TEXT('Günlük Rapor'!$A$3,"aaaa")&"_"&YEAR('Günlük Rapor'!$A$3)&" Portföy Analizi (1 - "&DAY(TODAY()-1)&" Haziran)"
B5: ='Opera Aylık Analiz'!G2 | D5: ='Opera Aylık Analiz'!F2 | F5: ='Opera Aylık Analiz'!AE2 | H5: ='Opera Aylık Analiz'!C2 | J5: ='Opera Aylık Analiz'!D2 | M5: ='Opera Aylık Analiz'!E2 | O5: ='Opera Aylık Analiz'!AH2
B6: ='Opera Aylık Analiz'!G3 | D6: ='Opera Aylık Analiz'!F3 | F6: ='Opera Aylık Analiz'!AE3 | H6: ='Opera Aylık Analiz'!C3 | J6: ='Opera Aylık Analiz'!D3 | L6: ='Opera Aylık Analiz'!E3 | O6: ='Opera Aylık Analiz'!AH3
B11: GİP Öncesi
B14: ='Opera Aylık Analiz'!M2 | D14: ='Opera Aylık Analiz'!S2 | F14: ='Opera Aylık Analiz'!U2 | H14: ='Opera Aylık Analiz'!V2 | J14: ='Opera Aylık Analiz'!W2
B15: ='Opera Aylık Analiz'!M3 | D15: ='Opera Aylık Analiz'!S3 | F15: ='Opera Aylık Analiz'!U3 | H15: ='Opera Aylık Analiz'!V3 | J15: ='Opera Aylık Analiz'!W3
B21: GİP Sonrası
B24: ='Opera Aylık Analiz'!Y2 | D24: ='Opera Aylık Analiz'!AG2 | F24: ='Opera Aylık Analiz'!AI2 | H24: ='Opera Aylık Analiz'!AJ2 | J24: ='Opera Aylık Analiz'!AK2
B25: ='Opera Aylık Analiz'!Y3 | D25: ='Opera Aylık Analiz'!AG3 | F25: ='Opera Aylık Analiz'!AI3 | H25: ='Opera Aylık Analiz'!AJ3 | J25: ='Opera Aylık Analiz'!AK3
B31: GİP Sonrası Fayda
B34: ='Opera Aylık Analiz'!AM2 | D34: ='Opera Aylık Analiz'!AN2 | F34: ='Opera Aylık Analiz'!AO2 | H34: ='Opera Aylık Analiz'!AP2
B35: ='Opera Aylık Analiz'!AM3 | D35: ='Opera Aylık Analiz'!AN3 | F35: ='Opera Aylık Analiz'!AO3 | H35: ='Opera Aylık Analiz'!AP3
B39: GES Üretim - Tutar
B42: GES Üretim (MWh) | D42: TUTAR (TL) | F42: TUTAR (USD)
B43: ='GES Üretim'!T3 | D43: ='GES Üretim'!O33 | F43: ='GES Üretim'!P33

Sheet Günlük Rapor
F1: GİP Öncesi | K1: GİP Sonrası
A2: Tarih | B2: UEVM(MWh) | C2: PTF (TL/MWh) | D2: SMF (TL/MWh) | E2: PTF (USD/MWh) | F2: İlk KUPST(TL) | G2: Toplam Maliyet(TL) | H2: Birim Maliyet(TL/MWh) | I2: Birim Maliyet(%) | J2: Dengesizlik Oranı (%) | K2: Son KUPST(TL) | L2: Toplam Maliyet(TL) | M2: Birim Maliyet(TL/MWh) | N2: Birim Maliyet(%) | O2: Dengesizlik Oranı (%) | P2: İdeal Tutar(TL) | Q2: Net Kazanılan Tutar(TL) | R2: KUPST Fayda(TL) | S2: GİP Sonrası KUPST İyileştirme Oranı(%) | T2: GİP Sonrası Toplam Fayda(TL) | U2: GİP Sonrası İyileştirme Oranı(%)
A3: 46204 | B3: ='Opera Günlük Analiz'!G3 | C3: ='Opera Günlük Analiz'!C3 | D3: ='Opera Günlük Analiz'!D3 | E3: ='Opera Günlük Analiz'!E3 | F3: ='Opera Günlük Analiz'!M3 | G3: ='Opera Günlük Analiz'!S3 | H3: ='Opera Günlük Analiz'!U3 | I3: ='Opera Günlük Analiz'!V3 | J3: ='Opera Günlük Analiz'!W3 | K3: ='Opera Günlük Analiz'!Y3 | L3: ='Opera Günlük Analiz'!AG3 | M3: ='Opera Günlük Analiz'!AI3 | N3: ='Opera Günlük Analiz'!AJ3 | O3: ='Opera Günlük Analiz'!AK3 | P3: ='Opera Günlük Analiz'!F3 | Q3: ='Opera Günlük Analiz'!AE3 | R3: =F3-K3 | S3: =IFERROR(R3/F3,0) | T3: =G3-L3 | U3: =IFERROR(T3/G3,0)
A4: =A3+1 | B4: ='Opera Günlük Analiz'!G4 | C4: ='Opera Günlük Analiz'!C4 | D4: ='Opera Günlük Analiz'!D4 | E4: ='Opera Günlük Analiz'!E4 | F4: ='Opera Günlük Analiz'!M4 | G4: ='Opera Günlük Analiz'!S4 | H4: ='Opera Günlük Analiz'!U4 | I4: ='Opera Günlük Analiz'!V4 | J4: ='Opera Günlük Analiz'!W4 | K4: ='Opera Günlük Analiz'!Y4 | L4: ='Opera Günlük Analiz'!AG4 | M4: ='Opera Günlük Analiz'!AI4 | N4: ='Opera Günlük Analiz'!AJ4 | O4: ='Opera Günlük Analiz'!AK4 | P4: ='Opera Günlük Analiz'!F4 | Q4: ='Opera Günlük Analiz'!AE4 | R4: =F4-K4 | S4: =IFERROR(R4/F4,0) | T4: =G4-L4 | U4: =IFERROR(T4/G4,0)
A5: =A4+1 | B5: ='Opera Günlük Analiz'!G5 | C5: ='Opera Günlük Analiz'!C5 | D5: ='Opera Günlük Analiz'!D5 | E5: ='Opera Günlük Analiz'!E5 | F5: ='Opera Günlük Analiz'!M5 | G5: ='Opera Günlük Analiz'!S5 | H5: ='Opera Günlük Analiz'!U5 | I5: ='Opera Günlük Analiz'!V5 | J5: ='Opera Günlük Analiz'!W5 | K5: ='Opera Günlük Analiz'!Y5 | L5: ='Opera Günlük Analiz'!AG5 | M5: ='Opera Günlük Analiz'!AI5 | N5: ='Opera Günlük Analiz'!AJ5 | O5: ='Opera Günlük Analiz'!AK5 | P5: ='Opera Günlük Analiz'!F5 | Q5: ='Opera Günlük Analiz'!AE5 | R5: =F5-K5 | S5: =IFERROR(R5/F5,0) | T5: =G5-L5 | U5: =IFERROR(T5/G5,0)
A6: =A5+1 | B6: ='Opera Günlük Analiz'!G6 | C6: ='Opera Günlük Analiz'!C6 | D6: ='Opera Günlük Analiz'!D6 | E6: ='Opera Günlük Analiz'!E6 | F6: ='Opera Günlük Analiz'!M6 | G6: ='Opera Günlük Analiz'!S6 | H6: ='Opera Günlük Analiz'!U6 | I6: ='Opera Günlük Analiz'!V6 | J6: ='Opera Günlük Analiz'!W6 | K6: ='Opera Günlük Analiz'!Y6 | L6: ='Opera Günlük Analiz'!AG6 | M6: ='Opera Günlük Analiz'!AI6 | N6: ='Opera Günlük Analiz'!AJ6 | O6: ='Opera Günlük Analiz'!AK6 | P6: ='Opera Günlük Analiz'!F6 | Q6: ='Opera Günlük Analiz'!AE6 | R6: =F6-K6 | S6: =IFERROR(R6/F6,0) | T6: =G6-L6 | U6: =IFERROR(T6/G6,0)
A7: =A6+1 | B7: ='Opera Günlük Analiz'!G7 | C7: ='Opera Günlük Analiz'!C7 | D7: ='Opera Günlük Analiz'!D7 | E7: ='Opera Günlük Analiz'!E7 | F7: ='Opera Günlük Analiz'!M7 | G7: ='Opera Günlük Analiz'!S7 | H7: ='Opera Günlük Analiz'!U7 | I7: ='Opera Günlük Analiz'!V7 | J7: ='Opera Günlük Analiz'!W7 | K7: ='Opera Günlük Analiz'!Y7 | L7: ='Opera Günlük Analiz'!AG7 | M7: ='Opera Günlük Analiz'!AI7 | N7: ='Opera Günlük Analiz'!AJ7 | O7: ='Opera Günlük Analiz'!AK7 | P7: ='Opera Günlük Analiz'!F7 | Q7: ='Opera Günlük Analiz'!AE7 | R7: =F7-K7 | S7: =IFERROR(R7/F7,0) | T7: =G7-L7 | U7: =IFERROR(T7/G7,0)
A8: =A7+1 | B8: ='Opera Günlük Analiz'!G8 | C8: ='Opera Günlük Analiz'!C8 | D8: ='Opera Günlük Analiz'!D8 | E8: ='Opera Günlük Analiz'!E8 | F8: ='Opera Günlük Analiz'!M8 | G8: ='Opera Günlük Analiz'!S8 | H8: ='Opera Günlük Analiz'!U8 | I8: ='Opera Günlük Analiz'!V8 | J8: ='Opera Günlük Analiz'!W8 | K8: ='Opera Günlük Analiz'!Y8 | L8: ='Opera Günlük Analiz'!AG8 | M8: ='Opera Günlük Analiz'!AI8 | N8: ='Opera Günlük Analiz'!AJ8 | O8: ='Opera Günlük Analiz'!AK8 | P8: ='Opera Günlük Analiz'!F8 | Q8: ='Opera Günlük Analiz'!AE8 | R8: =F8-K8 | S8: =IFERROR(R8/F8,0) | T8: =G8-L8 | U8: =IFERROR(T8/G8,0)
A9: =A8+1 | B9: ='Opera Günlük Analiz'!G9 | C9: ='Opera Günlük Analiz'!C9 | D9: ='Opera Günlük Analiz'!D9 | E9: ='Opera Günlük Analiz'!E9 | F9: ='Opera Günlük Analiz'!M9 | G9: ='Opera Günlük Analiz'!S9 | H9: ='Opera Günlük Analiz'!U9 | I9: ='Opera Günlük Analiz'!V9 | J9: ='Opera Günlük Analiz'!W9 | K9: ='Opera Günlük Analiz'!Y9 | L9: ='Opera Günlük Analiz'!AG9 | M9: ='Opera Günlük Analiz'!AI9 | N9: ='Opera Günlük Analiz'!AJ9 | O9: ='Opera Günlük Analiz'!AK9 | P9: ='Opera Günlük Analiz'!F9 | Q9: ='Opera Günlük Analiz'!AE9 | R9: =F9-K9 | S9: =IFERROR(R9/F9,0) | T9: =G9-L9 | U9: =IFERROR(T9/G9,0)
A10: =A9+1 | B10: ='Opera Günlük Analiz'!G10 | C10: ='Opera Günlük Analiz'!C10 | D10: ='Opera Günlük Analiz'!D10 | E10: ='Opera Günlük Analiz'!E10 | F10: ='Opera Günlük Analiz'!M10 | G10: ='Opera Günlük Analiz'!S10 | H10: ='Opera Günlük Analiz'!U10 | I10: ='Opera Günlük Analiz'!V10 | J10: ='Opera Günlük Analiz'!W10 | K10: ='Opera Günlük Analiz'!Y10 | L10: ='Opera Günlük Analiz'!AG10 | M10: ='Opera Günlük Analiz'!AI10 | N10: ='Opera Günlük Analiz'!AJ10 | O10: ='Opera Günlük Analiz'!AK10 | P10: ='Opera Günlük Analiz'!F10 | Q10: ='Opera Günlük Analiz'!AE10 | R10: =F10-K10 | S10: =IFERROR(R10/F10,0) | T10: =G10-L10 | U10: =IFERROR(T10/G10,0)
A11: =A10+1 | B11: ='Opera Günlük Analiz'!G11 | C11: ='Opera Günlük Analiz'!C11 | D11: ='Opera Günlük Analiz'!D11 | E11: ='Opera Günlük Analiz'!E11 | F11: ='Opera Günlük Analiz'!M11 | G11: ='Opera Günlük Analiz'!S11 | H11: ='Opera Günlük Analiz'!U11 | I11: ='Opera Günlük Analiz'!V11 | J11: ='Opera Günlük Analiz'!W11 | K11: ='Opera Günlük Analiz'!Y11 | L11: ='Opera Günlük Analiz'!AG11 | M11: ='Opera Günlük Analiz'!AI11 | N11: ='Opera Günlük Analiz'!AJ11 | O11: ='Opera Günlük Analiz'!AK11 | P11: ='Opera Günlük Analiz'!F11 | Q11: ='Opera Günlük Analiz'!AE11 | R11: =F11-K11 | S11: =IFERROR(R11/F11,0) | T11: =G11-L11 | U11: =IFERROR(T11/G11,0)
A12: =A11+1 | B12: ='Opera Günlük Analiz'!G12 | C12: ='Opera Günlük Analiz'!C12 | D12: ='Opera Günlük Analiz'!D12 | E12: ='Opera Günlük Analiz'!E12 | F12: ='Opera Günlük Analiz'!M12 | G12: ='Opera Günlük Analiz'!S12 | H12: ='Opera Günlük Analiz'!U12 | I12: ='Opera Günlük Analiz'!V12 | J12: ='Opera Günlük Analiz'!W12 | K12: ='Opera Günlük Analiz'!Y12 | L12: ='Opera Günlük Analiz'!AG12 | M12: ='Opera Günlük Analiz'!AI12 | N12: ='Opera Günlük Analiz'!AJ12 | O12: ='Opera Günlük Analiz'!AK12 | P12: ='Opera Günlük Analiz'!F12 | Q12: ='Opera Günlük Analiz'!AE12 | R12: =F12-K12 | S12: =IFERROR(R12/F12,0) | T12: =G12-L12 | U12: =IFERROR(T12/G12,0)
A13: =A12+1 | B13: ='Opera Günlük Analiz'!G13 | C13: ='Opera Günlük Analiz'!C13 | D13: ='Opera Günlük Analiz'!D13 | E13: ='Opera Günlük Analiz'!E13 | F13: ='Opera Günlük Analiz'!M13 | G13: ='Opera Günlük Analiz'!S13 | H13: ='Opera Günlük Analiz'!U13 | I13: ='Opera Günlük Analiz'!V13 | J13: ='Opera Günlük Analiz'!W13 | K13: ='Opera Günlük Analiz'!Y13 | L13: ='Opera Günlük Analiz'!AG13 | M13: ='Opera Günlük Analiz'!AI13 | N13: ='Opera Günlük Analiz'!AJ13 | O13: ='Opera Günlük Analiz'!AK13 | P13: ='Opera Günlük Analiz'!F13 | Q13: ='Opera Günlük Analiz'!AE13 | R13: =F13-K13 | S13: =IFERROR(R13/F13,0) | T13: =G13-L13 | U13: =IFERROR(T13/G13,0)
A14: =A13+1 | B14: ='Opera Günlük Analiz'!G14 | C14: ='Opera Günlük Analiz'!C14 | D14: ='Opera Günlük Analiz'!D14 | E14: ='Opera Günlük Analiz'!E14 | F14: ='Opera Günlük Analiz'!M14 | G14: ='Opera Günlük Analiz'!S14 | H14: ='Opera Günlük Analiz'!U14 | I14: ='Opera Günlük Analiz'!V14 | J14: ='Opera Günlük Analiz'!W14 | K14: ='Opera Günlük Analiz'!Y14 | L14: ='Opera Günlük Analiz'!AG14 | M14: ='Opera Günlük Analiz'!AI14 | N14: ='Opera Günlük Analiz'!AJ14 | O14: ='Opera Günlük Analiz'!AK14 | P14: ='Opera Günlük Analiz'!F14 | Q14: ='Opera Günlük Analiz'!AE14 | R14: =F14-K14 | S14: =IFERROR(R14/F14,0) | T14: =G14-L14 | U14: =IFERROR(T14/G14,0)
A15: =A14+1 | B15: ='Opera Günlük Analiz'!G15 | C15: ='Opera Günlük Analiz'!C15 | D15: ='Opera Günlük Analiz'!D15 | E15: ='Opera Günlük Analiz'!E15 | F15: ='Opera Günlük Analiz'!M15 | G15: ='Opera Günlük Analiz'!S15 | H15: ='Opera Günlük Analiz'!U15 | I15: ='Opera Günlük Analiz'!V15 | J15: ='Opera Günlük Analiz'!W15 | K15: ='Opera Günlük Analiz'!Y15 | L15: ='Opera Günlük Analiz'!AG15 | M15: ='Opera Günlük Analiz'!AI15 | N15: ='Opera Günlük Analiz'!AJ15 | O15: ='Opera Günlük Analiz'!AK15 | P15: ='Opera Günlük Analiz'!F15 | Q15: ='Opera Günlük Analiz'!AE15 | R15: =F15-K15 | S15: =IFERROR(R15/F15,0) | T15: =G15-L15 | U15: =IFERROR(T15/G15,0)
... A33: =A32+1 | B33: ='Opera Günlük Analiz'!G33 | C33: ='Opera Günlük Analiz'!C33 | D33: ='Opera Günlük Analiz'!D33 | E33: ='Opera Günlük Analiz'!E33 | F33: ='Opera Günlük Analiz'!M33 | G33: ='Opera Günlük Analiz'!S33 | H33: ='Opera Günlük Analiz'!U33 | I33: ='Opera Günlük Analiz'!V33 | J33: ='Opera Günlük Analiz'!W33 | K33: ='Opera Günlük Analiz'!Y33 | L33: ='Opera Günlük Analiz'!AG33 | M33: ='Opera Günlük Analiz'!AI33 | N33: ='Opera Günlük Analiz'!AJ33 | O33: ='Opera Günlük Analiz'!AK33 | P33: ='Opera Günlük Analiz'!F33 | Q33: ='Opera Günlük Analiz'!AE33 | R33: =F33-K33 | S33: =IFERROR(R33/F33,0) | T33: =G33-L33 | U33: =IFERROR(T33/G33,0)
A34: Toplam | B34: ='Opera Aylık Analiz'!$G$3 | C34: ='Opera Aylık Analiz'!$C$3 | D34: ='Opera Aylık Analiz'!$D$3 | E34: ='Opera Aylık Analiz'!$E$3 | F34: ='Opera Aylık Analiz'!$M$3 | G34: ='Opera Aylık Analiz'!$S$3 | H34: ='Opera Aylık Analiz'!$U$3 | I34: ='Opera Aylık Analiz'!$V$3 | J34: ='Opera Aylık Analiz'!$W$3 | K34: ='Opera Aylık Analiz'!$Y$3 | L34: ='Opera Aylık Analiz'!$AG$3 | M34: ='Opera Aylık Analiz'!$AI$3 | N34: ='Opera Aylık Analiz'!$AJ$3 | O34: ='Opera Aylık Analiz'!$AK$3 | P34: ='Opera Aylık Analiz'!$F$3 | Q34: ='Opera Aylık Analiz'!$AE$3 | R34: ='Opera Aylık Analiz'!$AM$3 | S34: ='Opera Aylık Analiz'!$AN$3 | T34: ='Opera Aylık Analiz'!$AO$3 | U34: ='Opera Aylık Analiz'!$AP$3
F38: GİP Öncesi | K38: GİP Sonrası
A39: Dönem | B39: UEVM(MWh) | C39: PTF (TL/MWh) | D39: SMF (TL/MWh) | E39: PTF (USD/MWh) | F39: İlk KUPST(TL) | G39: Toplam Maliyet(TL) | H39: Birim Maliyet(TL/MWh) | I39: Birim Maliyet(%) | J39: Dengesizlik Oranı (%) | K39: Son KUPST(TL) | L39: Toplam Maliyet(TL) | M39: Birim Maliyet(TL/MWh) | N39: Birim Maliyet(%) | O39: Dengesizlik Oranı (%) | Q39: Net Kazanılan Tutar(TL) | R39: KUPST Fayda(TL) | S39: GİP Sonrası KUPST İyileştirme Oranı(%) | T39: GİP Sonrası Toplam Fayda(TL) | U39: GİP Sonrası İyileştirme Oranı(%)
A40: 46023 | B40: 4729.76 | C40: 2894.9207 | D40: 2760.6393 | E40: 67.200538 | F40: 144921.45 | G40: 557801.23 | H40: 117.93436 | I40: 0.040295019 | J40: 0.23785139 | K40: 36768.622 | L40: 157309.38 | M40: 33.259484 | N40: 0.011363877 | O40: 0.038027299 | P40: 13842932 | Q40: 13685623 | R40: 108152.83 | S40: 0.74628586 | T40: 400491.85 | U40: 0.71798309
A41: 46054 | B41: 18430.5 | C41: 2078.195 | D41: 1865.8934 | E41: 47.72869 | F41: 426549.2 | G41: 3110222.7 | H41: 168.75411 | I41: 0.074620424 | J41: 0.229296 | K41: 85820.793 | L41: 873077.26 | M41: 47.371328 | N41: 0.020946859 | O41: 0.036545943 | P41: 41680582 | Q41: 40807505 | R41: 340728.41 | S41: 0.79880213 | T41: 2237145.4 | U41: 0.71928786
A42: 46082 | B42: 15270.75 | C42: 1620.3243 | D42: 1687.6174 | E42: 36.808898 | F42: 290732.74 | G42: 1671137.1 | H42: 109.43386 | I42: 0.06288736 | J42: 0.22710279 | K42: 33224.971 | L42: 269969.65 | M42: 17.678873 | N42: 0.010159357 | O42: 0.018416253 | P42: 26573498 | Q42: 26303528 | R42: 257507.77 | S42: 0.88571989 | T42: 1401167.5 | U42: 0.83845153
A43: 46113 | B43: 16987.25 | C43: 921.05657 | D43: 1185.861 | E43: 20.655069 | F43: 214516.66 | G43: 1250898.6 | H43: 73.637501 | I43: 0.062474492 | J43: 0.16042444 | K43: 41503.683 | L43: 307869.48 | M43: 18.123562 | N43: 0.015376137 | O43: 0.024801542 | P43: 20022550 | Q43: 19714681 | R43: 173012.98 | S43: 0.80652466 | T43: 943029.16 | U43: 0.75388135
A44: 46143 | B44: 13232.71 | C44: 590.89999 | D44: 875.2954 | E44: 13.047863 | F44: 299608.6 | G44: 2123120.9 | H44: 160.44491 | I44: 0.12826486 | J44: 0.26845824 | K44: 58086.092 | L44: 228774.59 | M44: 17.288567 | N44: 0.01382104 | O44: 0.036597946 | P44: 16552632 | Q44: 16323857 | R44: 241522.51 | S44: 0.80612675 | T44: 1894346.3 | U44: 0.89224609
A45: 46174 | B45: 20294 | C45: 1240 | D45: 1761 | E45: 26.89 | F45: 223160 | G45: 1395216 | H45: 68.75 | I45: 0.0424 | J45: 0.1451 | K45: 22997 | L45: -267679 | M45: -13.19 | N45: -0.0081 | O45: 0.0165 | P45: 32923516 | Q45: 33191195 | R45: 200163 | S45: 0.9 | T45: 1662894 | U45: 1.19
A46: 46204 | B46: =B34 | C46: =C34 | D46: =D34 | E46: =E34 | F46: =F34 | G46: =G34 | H46: =H34 | I46: =I34 | ... U46: =U34

Sheet GES Üretim
A1: Tarih | B1: Saat | C1: GÜN | D1: AY | E1: Üretim Miktarı | F1: PTF (TL/MWh) | G1: PTF (USD/MWh) | H1: Tutar (TL) | I1: Tutar (USD) | M1: Tarih | N1: UEVM(MWh) | O1: Tutar (TL) | P1: Tutar (USD)
A2: =[1]FİYATLAR!A2 | B2: =[1]FİYATLAR!B2 | C2: =INT(A2) | D2: =MONTH(A2) | E2: 0 | F2: =[1]FİYATLAR!C2 | G2: =[1]FİYATLAR!D2 | H2: =E2*F2 | I2: =E2*G2 | M2: 46204 | N2: =SUMIF(C:C,M2,E:E) | O2: =SUMIF(C:C,M2,H:H) | P2: =SUMIF(C:C,M2,I:I) | T2: Üretim Miktarı | U2: Tutar (TL) | V2: Tutar (USD)
A3: =[1]FİYATLAR!A3 | B3: =[1]FİYATLAR!B3 | C3: =INT(A3) | D3: =MONTH(A3) | E3: 0 | F3: =[1]FİYATLAR!C3 | G3: =[1]FİYATLAR!D3 | H3: =E3*F3 | I3: =E3*G3 | M3: =M2+1 | N3: =SUMIF(C:C,M3,E:E) | O3: =SUMIF(C:C,M3,H:H) | P3: =SUMIF(C:C,M3,I:I) | S3: GES | T3: ='GES Üretim'!N33 | U3: ='GES Üretim'!O33 | V3: ='GES Üretim'!P33
A4: =[1]FİYATLAR!A4 | B4: =[1]FİYATLAR!B4 | C4: =INT(A4) | D4: =MONTH(A4) | E4: 0 | F4: =[1]FİYATLAR!C4 | G4: =[1]FİYATLAR!D4 | H4: =E4*F4 | I4: =E4*G4 | M4: =M3+1 | N4: =SUMIF(C:C,M4,E:E) | O4: =SUMIF(C:C,M4,H:H) | P4: =SUMIF(C:C,M4,I:I)
A5: =[1]FİYATLAR!A5 | B5: =[1]FİYATLAR!B5 | C5: =INT(A5) | D5: =MONTH(A5) | E5: 0 | F5: =[1]FİYATLAR!C5 | G5: =[1]FİYATLAR!D5 | H5: =E5*F5 | I5: =E5*G5 | M5: =M4+1 | N5: =SUMIF(C:C,M5,E:E) | O5: =SUMIF(C:C,M5,H:H) | P5: =SUMIF(C:C,M5,I:I)
A6: =[1]FİYATLAR!A6 | B6: =[1]FİYATLAR!B6 | C6: =INT(A6) | D6: =MONTH(A6) | E6: 0 | F6: =[1]FİYATLAR!C6 | G6: =[1]FİYATLAR!D6 | H6: =E6*F6 | I6: =E6*G6 | M6: =M5+1 | N6: =SUMIF(C:C,M6,E:E) | O6: =SUMIF(C:C,M6,H:H) | P6: =SUMIF(C:C,M6,I:I)
A7: =[1]FİYATLAR!A7 | B7: =[1]FİYATLAR!B7 | C7: =INT(A7) | D7: =MONTH(A7) | E7: 0 | F7: =[1]FİYATLAR!C7 | G7: =[1]FİYATLAR!D7 | H7: =E7*F7 | I7: =E7*G7 | M7: =M6+1 | N7: =SUMIF(C:C,M7,E:E) | O7: =SUMIF(C:C,M7,H:H) | P7: =SUMIF(C:C,M7,I:I)
A8: =[1]FİYATLAR!A8 | B8: =[1]FİYATLAR!B8 | C8: =INT(A8) | D8: =MONTH(A8) | E8: 0.06 | F8: =[1]FİYATLAR!C8 | G8: =[1]FİYATLAR!D8 | H8: =E8*F8 | I8: =E8*G8 | M8: =M7+1 | N8: =SUMIF(C:C,M8,E:E) | O8: =SUMIF(C:C,M8,H:H) | P8: =SUMIF(C:C,M8,I:I)
A9: =[1]FİYATLAR!A9 | B9: =[1]FİYATLAR!B9 | C9: =INT(A9) | D9: =MONTH(A9) | E9: 0.42 | F9: =[1]FİYATLAR!C9 | G9: =[1]FİYATLAR!D9 | H9: =E9*F9 | I9: =E9*G9 | M9: =M8+1 | N9: =SUMIF(C:C,M9,E:E) | O9: =SUMIF(C:C,M9,H:H) | P9: =SUMIF(C:C,M9,I:I)
A10: =[1]FİYATLAR!A10 | B10: =[1]FİYATLAR!B10 | C10: =INT(A10) | D10: =MONTH(A10) | E10: 0.87 | F10: =[1]FİYATLAR!C10 | G10: =[1]FİYATLAR!D10 | H10: =E10*F10 | I10: =E10*G10 | M10: =M9+1 | N10: =SUMIF(C:C,M10,E:E) | O10: =SUMIF(C:C,M10,H:H) | P10: =SUMIF(C:C,M10,I:I)
A11: =[1]FİYATLAR!A11 | B11: =[1]FİYATLAR!B11 | C11: =INT(A11) | D11: =MONTH(A11) | E11: 1.26 | F11: =[1]FİYATLAR!C11 | G11: =[1]FİYATLAR!D11 | H11: =E11*F11 | I11: =E11*G11 | M11: =M10+1 | N11: =SUMIF(C:C,M11,E:E) | O11: =SUMIF(C:C,M11,H:H) | P11: =SUMIF(C:C,M11,I:I)
A12: =[1]FİYATLAR!A12 | B12: =[1]FİYATLAR!B12 | C12: =INT(A12) | D12: =MONTH(A12) | E12: 1.56 | F12: =[1]FİYATLAR!C12 | G12: =[1]FİYATLAR!D12 | H12: =E12*F12 | I12: =E12*G12 | M12: =M11+1 | N12: =SUMIF(C:C,M12,E:E) | O12: =SUMIF(C:C,M12,H:H) | P12: =SUMIF(C:C,M12,I:I)
A13: =[1]FİYATLAR!A13 | B13: =[1]FİYATLAR!B13 | C13: =INT(A13) | D13: =MONTH(A13) | E13: 1.74 | F13: =[1]FİYATLAR!C13 | G13: =[1]FİYATLAR!D13 | H13: =E13*F13 | I13: =E13*G13 | M13: =M12+1 | N13: =SUMIF(C:C,M13,E:E) | O13: =SUMIF(C:C,M13,H:H) | P13: =SUMIF(C:C,M13,I:I)
A14: =[1]FİYATLAR!A14 | B14: =[1]FİYATLAR!B14 | C14: =INT(A14) | D14: =MONTH(A14) | E14: 1.81 | F14: =[1]FİYATLAR!C14 | G14: =[1]FİYATLAR!D14 | H14: =E14*F14 | I14: =E14*G14 | M14: =M13+1 | N14: =SUMIF(C:C,M14,E:E) | O14: =SUMIF(C:C,M14,H:H) | P14: =SUMIF(C:C,M14,I:I)
A15: =[1]FİYATLAR!A15 | B15: =[1]FİYATLAR!B15 | C15: =INT(A15) | D15: =MONTH(A15) | E15: 1.78 | F15: =[1]FİYATLAR!C15 | G15: =[1]FİYATLAR!D15 | H15: =E15*F15 | I15: =E15*G15 | M15: =M14+1 | N15: =SUMIF(C:C,M15,E:E) | O15: =SUMIF(C:C,M15,H:H) | P15: =SUMIF(C:C,M15,I:I)
... A32: =[1]FİYATLAR!A32 | B32: =[1]FİYATLAR!B32 | C32: =INT(A32) | D32: =MONTH(A32) | E32: 0.08 | F32: =[1]FİYATLAR!C32 | G32: =[1]FİYATLAR!D32 | H32: =E32*F32 | I32: =E32*G32 | M32: =M31+1 | N32: =SUMIF(C:C,M32,E:E) | O32: =SUMIF(C:C,M32,H:H) | P32: =SUMIF(C:C,M32,I:I)
A33: =[1]FİYATLAR!A33 | B33: =[1]FİYATLAR!B33 | C33: =INT(A33) | D33: =MONTH(A33) | E33: 0.43 | F33: =[1]FİYATLAR!C33 | G33: =[1]FİYATLAR!D33 | H33: =E33*F33 | I33: =E33*G33 | M33: Toplam | N33: =SUM(N2:N32) | O33: =SUM(O2:O32) | P33: =SUM(P2:P32)
A34: =[1]FİYATLAR!A34 | B34: =[1]FİYATLAR!B34 | C34: =INT(A34) | D34: =MONTH(A34) | E34: 0.89 | F34: =[1]FİYATLAR!C34 | G34: =[1]FİYATLAR!D34 | H34: =E34*F34 | I34: =E34*G34
A35: =[1]FİYATLAR!A35 | B35: =[1]FİYATLAR!B35 | C35: =INT(A35) | D35: =MONTH(A35) | E35: 1.27 | F35: =[1]FİYATLAR!C35 | G35: =[1]FİYATLAR!D35 | H35: =E35*F35 | I35: =E35*G35
A36: =[1]FİYATLAR!A36 | B36: =[1]FİYATLAR!B36 | C36: =INT(A36) | D36: =MONTH(A36) | E36: 1.54 | F36: =[1]FİYATLAR!C36 | G36: =[1]FİYATLAR!D36 | H36: =E36*F36 | I36: =E36*G36
A37: =[1]FİYATLAR!A37 | B37: =[1]FİYATLAR!B37 | C37: =INT(A37) | D37: =MONTH(A37) | E37: 1.71 | F37: =[1]FİYATLAR!C37 | G37: =[1]FİYATLAR!D37 | H37: =E37*F37 | I37: =E37*G37
A38: =[1]FİYATLAR!A38 | B38: =[1]FİYATLAR!B38 | C38: =INT(A38) | D38: =MONTH(A38) | E38: 1.78 | F38: =[1]FİYATLAR!C38 | G38: =[1]FİYATLAR!D38 | H38: =E38*F38 | I38: =E38*G38
A39: =[1]FİYATLAR!A39 | B39: =[1]FİYATLAR!B39 | C39: =INT(A39) | D39: =MONTH(A39) | E39: 1.74 | F39: =[1]FİYATLAR!C39 | G39: =[1]FİYATLAR!D39 | H39: =E39*F39 | I39: =E39*G39
A40: =[1]FİYATLAR!A40 | B40: =[1]FİYATLAR!B40 | C40: =INT(A40) | D40: =MONTH(A40) | E40: 1.61 | F40: =[1]FİYATLAR!C40 | G40: =[1]FİYATLAR!D40 | H40: =E40*F40 | I40: =E40*G40
A41: =[1]FİYATLAR!A41 | B41: =[1]FİYATLAR!B41 | C41: =INT(A41) | D41: =MONTH(A41) | E41: 1.38 | F41: =[1]FİYATLAR!C41 | G41: =[1]FİYATLAR!D41 | H41: =E41*F41 | I41: =E41*G41
A42: =[1]FİYATLAR!A42 | B42: =[1]FİYATLAR!B42 | C42: =INT(A42) | D42: =MONTH(A42) | E42: 1.04 | F42: =[1]FİYATLAR!C42 | G42: =[1]FİYATLAR!D42 | H42: =E42*F42 | I42: =E42*G42
A43: =[1]FİYATLAR!A43 | B43: =[1]FİYATLAR!B43 | C43: =INT(A43) | D43: =MONTH(A43) | E43: 0.61 | F43: =[1]FİYATLAR!C43 | G43: =[1]FİYATLAR!D43 | H43: =E43*F43 | I43: =E43*G43
A44: =[1]FİYATLAR!A44 | B44: =[1]FİYATLAR!B44 | C44: =INT(A44) | D44: =MONTH(A44) | E44: 0.22 | F44: =[1]FİYATLAR!C44 | G44: =[1]FİYATLAR!D44 | H44: =E44*F44 | I44: =E44*G44
A45: =[1]FİYATLAR!A45 | B45: =[1]FİYATLAR!B45 | C45: =INT(A45) | D45: =MONTH(A45) | E45: 0.01 | F45: =[1]FİYATLAR!C45 | G45: =[1]FİYATLAR!D45 | H45: =E45*F45 | I45: =E45*G45
... A193: =[1]FİYATLAR!A193 | B193: =[1]FİYATLAR!B193 | C193: =INT(A193) | D193: =MONTH(A193) | E193: 0 | F193: =[1]FİYATLAR!C193 | G193: =[1]FİYATLAR!D193 | H193: =E193*F193 | I193: =E193*G193
A194: =[1]FİYATLAR!A194 | B194: =[1]FİYATLAR!B194 | C194: =INT(A194) | D194: =MONTH(A194) | F194: =[1]FİYATLAR!C194 | G194: =[1]FİYATLAR!D194 | H194: =E194*F194 | I194: =E194*G194
A195: =[1]FİYATLAR!A195 | B195: =[1]FİYATLAR!B195 | C195: =INT(A195) | D195: =MONTH(A195) | F195: =[1]FİYATLAR!C195 | G195: =[1]FİYATLAR!D195 | H195: =E195*F195 | I195: =E195*G195
A196: =[1]FİYATLAR!A196 | B196: =[1]FİYATLAR!B196 | C196: =INT(A196) | D196: =MONTH(A196) | F196: =[1]FİYATLAR!C196 | G196: =[1]FİYATLAR!D196 | H196: =E196*F196 | I196: =E196*G196
A197: =[1]FİYATLAR!A197 | B197: =[1]FİYATLAR!B197 | C197: =INT(A197) | D197: =MONTH(A197) | F197: =[1]FİYATLAR!C197 | G197: =[1]FİYATLAR!D197 | H197: =E197*F197 | I197: =E197*G197
A198: =[1]FİYATLAR!A198 | B198: =[1]FİYATLAR!B198 | C198: =INT(A198) | D198: =MONTH(A198) | F198: =[1]FİYATLAR!C198 | G198: =[1]FİYATLAR!D198 | H198: =E198*F198 | I198: =E198*G198
A199: =[1]FİYATLAR!A199 | B199: =[1]FİYATLAR!B199 | C199: =INT(A199) | D199: =MONTH(A199) | F199: =[1]FİYATLAR!C199 | G199: =[1]FİYATLAR!D199 | H199: =E199*F199 | I199: =E199*G199
A200: =[1]FİYATLAR!A200 | B200: =[1]FİYATLAR!B200 | C200: =INT(A200) | D200: =MONTH(A200) | F200: =[1]FİYATLAR!C200 | G200: =[1]FİYATLAR!D200 | H200: =E200*F200 | I200: =E200*G200
A201: =[1]FİYATLAR!A201 | B201: =[1]FİYATLAR!B201 | C201: =INT(A201) | D201: =MONTH(A201) | F201: =[1]FİYATLAR!C201 | G201: =[1]FİYATLAR!D201 | H201: =E201*F201 | I201: =E201*G201
A202: =[1]FİYATLAR!A202 | B202: =[1]FİYATLAR!B202 | C202: =INT(A202) | D202: =MONTH(A202) | F202: =[1]FİYATLAR!C202 | G202: =[1]FİYATLAR!D202 | H202: =E202*F202 | I202: =E202*G202
A203: =[1]FİYATLAR!A203 | B203: =[1]FİYATLAR!B203 | C203: =INT(A203) | D203: =MONTH(A203) | F203: =[1]FİYATLAR!C203 | G203: =[1]FİYATLAR!D203 | H203: =E203*F203 | I203: =E203*G203
...

Sheet Opera Aylık Analiz
M1: GİP ÖNCESİ | Y1: GİP SONRASI
B2: AY | C2: PTF (TL/MWh) | D2: SMF (TL/MWh) | E2: PTF (USD/MWh) | F2: İdeal Tutar(TL) | G2: UEVM(MWh) | H2: A.O. PTF(TL/MWh) | I2: GÖP Tahmini Üretim (MWh) | J2: GÖP Tutar(TL) | K2: İA Tutar(TL) | L2: GİP Tutar(TL) | M2: İlk KUPST(TL) | N2: Mutlak EDM(MWh) | O2: EDM(MWh) | P2: EDT(TL) | Q2: Net Kazanılan Tutar(TL) | R2: Dengesizlik Maliyeti(TL) | S2: Toplam Maliyet(TL) | T2: A.O. PTF(TL/MWh) | U2: Birim Maliyet(TL/MWh) | V2: Birim Maliyet(%) | W2: Dengesizlik Oranı (%) | X2: Dengesizlik Oranı>%10 Miktarı | Y2: Son KUPST(TL) | Z2: Mutlak EDM(MWh) | AA2: EDM(MWh) | AB2: EDT(TL) | AC2: Dengesizlik Maliyeti_Yeni | AD2: Birim Maliyeti_Yeni | AE2: Net Kazanılan Tutar(TL) | AF2: Dengesizlik Maliyeti(TL) | AG2: Toplam Maliyet(TL) | AH2: A.O. PTF(TL/MWh) | AI2: Birim Maliyet(TL/MWh) | AJ2: Birim Maliyet(%) | AK2: Dengesizlik Oranı (%) | AL2: Dengesizlik Oranı>%10 Miktarı | AM2: KUPST Fayda(TL) | AN2: GİP Sonrası KUPST İyileştirme Oranı(%) | AO2: GİP Sonrası Toplam Fayda(TL) | AP2: GİP Sonrası İyileştirme Oranı(%)
A3: 7 | B3: 46204 | C3: =AVERAGEIF('Opera Enerji Veri'!$D:$D,'Opera Aylık Analiz'!$A3,'Opera Enerji Veri'!F:F) | D3: =AVERAGEIF('Opera Enerji Veri'!$D:$D,'Opera Aylık Analiz'!$A3,'Opera Enerji Veri'!G:G) | E3: =AVERAGEIF('Opera Enerji Veri'!$D:$D,'Opera Aylık Analiz'!$A3,'Opera Enerji Veri'!H:H) | F3: =SUMIF('Opera Enerji Veri'!$D:$D, $A3,'Opera Enerji Veri'!BE:BE) | G3: =SUMIF('Opera Enerji Veri'!$D:$D, $A3,'Opera Enerji Veri'!AY:AY) | H3: =F3/G3 | I3: =SUMIF('Opera Enerji Veri'!$D:$D, $A3,'Opera Enerji Veri'!J:J) | J3: =SUMIF('Opera Enerji Veri'!$D:$D, $A3,'Opera Enerji Veri'!BF:BF) | K3: =SUMIF('Opera Enerji Veri'!$D:$D, $A3,'Opera Enerji Veri'!BG:BG) | L3: =SUMIF('Opera Enerji Veri'!$D:$D, $A3,'Opera Enerji Veri'!BH:BH) | M3: =SUMIF('Opera Enerji Veri'!$D:$D, $A3,'Opera Enerji Veri'!BB:BB) | N3: =SUMIF('Opera Enerji Veri'!$D:$D, $A3,'Opera Enerji Veri'!BJ:BJ) | O3: =SUMIF('Opera Enerji Veri'!$D:$D, $A3,'Opera Enerji Veri'!BK:BK) | P3: =SUMIF('Opera Enerji Veri'!$D:$D, $A3,'Opera Enerji Veri'!BL:BL) | Q3: =J3+K3+P3-M3 | R3: =F3-Q3-M3 | S3: =F3-Q3 | T3: =Q3/G3 | U3: =IFERROR(S3/G3,0) | V3: =IFERROR(U3/H3,0) | W3: =N3/G3 | X3: =SUMIF('Opera Enerji Veri'!$D:$D, $A3,'Opera Enerji Veri'!BU:BU) | Y3: =SUMIF('Opera Enerji Veri'!$D:$D, $A3,'Opera Enerji Veri'!BD:BD) | Z3: =SUMIF('Opera Enerji Veri'!$D:$D, $A3,'Opera Enerji Veri'!BW:BW) | AA3: =SUMIF('Opera Enerji Veri'!$D:$D, $A3,'Opera Enerji Veri'!BX:BX) | AB3: =SUMIF('Opera Enerji Veri'!$D:$D, $A3,'Opera Enerji Veri'!BY:BY) | AC3: =SUMIF('Opera Enerji Veri'!$D:$D, $A3,'Opera Enerji Veri'!CI:CI) | AD3: =AC3/G3 | AE3: =J3+K3+L3+AB3-Y3 | AF3: =F3-AE3-Y3 | AG3: =F3-AE3 | AH3: =AE3/G3 | AI3: =IF(G3=0,0,AG3/G3) | AJ3: =IFERROR(AI3/H3,0) | AK3: =Z3/G3 | AL3: =SUMIF('Opera Enerji Veri'!$D:$D, $A3,'Opera Enerji Veri'!CH:CH) | AM3: =M3-Y3 | AN3: =AM3/M3 | AO3: =S3-AG3 | AP3: =AO3/S3

Sheet Opera Günlük Analiz
M1: GİP ÖNCESİ | Y1: GİP SONRASI
B2: TARİH | C2: PTF (TL/MWh) | D2: SMF (TL/MWh) | E2: PTF (USD/MWh) | F2: İdeal Tutar(TL) | G2: UEVM(MWh) | H2: A.O. PTF(TL/MWh) | I2: GÖP Tahmini Üretim (MWh) | J2: GÖP Tutar(TL) | K2: İA Tutar(TL) | L2: GİP Tutar(TL) | M2: İlk KUPST(TL) | N2: Mutlak EDM(MWh) | O2: EDM(MWh) | P2: EDT(TL) | Q2: NET GELİR(TL) | R2: Dengesizlik Maliyeti(TL) | S2: TOPLAM MALİYET(TL) | T2: A.O. PTF(TL/MWh) | U2: Birim Maliyet(TL/MWh) | V2: Birim Maliyet(%) | W2: Dengesizlik Oranı (%) | X2: Dengesizlik Oranı>%10 Miktarı | Y2: Son KUPST(TL) | Z2: Mutlak EDM(MWh) | AA2: EDM(MWh) | AB2: EDT(TL) | AC2: Dengesizlik Maliyeti_Yeni | AD2: Birim Maliyeti_Yeni | AE2: NET GELİR(TL) | AF2: Dengesizlik Maliyeti(TL) | AG2: Toplam Maliyet(TL) | AH2: A.O. PTF(TL/MWh) | AI2: Birim Maliyet(TL/MWh) | AJ2: Birim Maliyet(%) | AK2: Dengesizlik Oranı (%) | AL2: Dengesizlik Oranı>%10 Miktarı | AM2: KUPST Fayda(TL) | AN2: GİP Sonrası KUPST İyileştirme Oranı(%) | AO2: GİP Sonrası Toplam Fayda(TL) | AP2: GİP Sonrası İyileştirme Oranı(%)
B3: 46204 | C3: =IFERROR(AVERAGEIF('Opera Enerji Veri'!$C:$C,'Opera Günlük Analiz'!$B3,'Opera Enerji Veri'!F:F),0) | D3: =IFERROR(AVERAGEIF('Opera Enerji Veri'!$C:$C,'Opera Günlük Analiz'!$B3,'Opera Enerji Veri'!G:G),0) | E3: =IFERROR(AVERAGEIF('Opera Enerji Veri'!$C:$C,'Opera Günlük Analiz'!$B3,'Opera Enerji Veri'!H:H),0) | F3: =SUMIF('Opera Enerji Veri'!$C:$C, 'Opera Günlük Analiz'!$B3,'Opera Enerji Veri'!BE:BE) | G3: =SUMIF('Opera Enerji Veri'!$C:$C, 'Opera Günlük Analiz'!$B3,'Opera Enerji Veri'!AY:AY) | H3: =IFERROR(F3/G3,0) | I3: =SUMIF('Opera Enerji Veri'!$C:$C, 'Opera Günlük Analiz'!$B3,'Opera Enerji Veri'!J:J) | J3: =SUMIF('Opera Enerji Veri'!$C:$C, 'Opera Günlük Analiz'!$B3,'Opera Enerji Veri'!BF:BF) | K3: =SUMIF('Opera Enerji Veri'!$C:$C, 'Opera Günlük Analiz'!$B3,'Opera Enerji Veri'!BG:BG) | L3: =SUMIF('Opera Enerji Veri'!$C:$C, 'Opera Günlük Analiz'!$B3,'Opera Enerji Veri'!BH:BH) | M3: =SUMIF('Opera Enerji Veri'!$C:$C, 'Opera Günlük Analiz'!$B3,'Opera Enerji Veri'!BB:BB) | N3: =SUMIF('Opera Enerji Veri'!$C:$C, 'Opera Günlük Analiz'!$B3,'Opera Enerji Veri'!BJ:BJ) | O3: =SUMIF('Opera Enerji Veri'!$C:$C, 'Opera Günlük Analiz'!$B3,'Opera Enerji Veri'!BK:BK) | P3: =SUMIF('Opera Enerji Veri'!$C:$C, 'Opera Günlük Analiz'!$B3,'Opera Enerji Veri'!BL:BL) | Q3: =J3+K3+P3-M3 | R3: =F3-Q3-M3 | S3: =M3+R3 | T3: =IFERROR(Q3/G3,0) | U3: =IF(G3=0,0,S3/G3) | V3: =IFERROR(U3/H3,0) | W3: =IFERROR(ABS(N3/G3),0) | X3: =SUMIF('Opera Enerji Veri'!$C:$C, 'Opera Günlük Analiz'!$B3,'Opera Enerji Veri'!BU:BU) | Y3: =SUMIF('Opera Enerji Veri'!$C:$C, 'Opera Günlük Analiz'!$B3,'Opera Enerji Veri'!BD:BD) | Z3: =SUMIF('Opera Enerji Veri'!$C:$C, 'Opera Günlük Analiz'!$B3,'Opera Enerji Veri'!BW:BW) | AA3: =SUMIF('Opera Enerji Veri'!$C:$C, 'Opera Günlük Analiz'!$B3,'Opera Enerji Veri'!BX:BX) | AB3: =SUMIF('Opera Enerji Veri'!$C:$C, 'Opera Günlük Analiz'!$B3,'Opera Enerji Veri'!BY:BY) | AC3: =SUMIF('Opera Enerji Veri'!$C:$C, 'Opera Günlük Analiz'!$B3,'Opera Enerji Veri'!CI:CI) | AD3: =IFERROR(AC3/G3,0) | AE3: =J3+K3+L3+AB3-Y3 | AF3: =F3-AE3-Y3 | AG3: =Y3+AF3 | AH3: =IFERROR(AE3/G3,0) | AI3: =IF(G3=0,0,AG3/G3) | AJ3: =IFERROR(AI3/H3,0) | AK3: =IFERROR(ABS(Z3/G3),0) | AL3: =SUMIF('Opera Enerji Veri'!$C:$C, 'Opera Günlük Analiz'!$B3,'Opera Enerji Veri'!CH:CH) | AM3: =M3-Y3 | AN3: =IFERROR(AM3/M3,0) | AO3: =S3-AG3 | AP3: =IFERROR(AO3/S3,0)
B4: =B3+1 | C4: =IFERROR(AVERAGEIF('Opera Enerji Veri'!C:C,'Opera Günlük Analiz'!B4,'Opera Enerji Veri'!F:F),0) | D4: =IFERROR(AVERAGEIF('Opera Enerji Veri'!$C:$C,'Opera Günlük Analiz'!$B4,'Opera Enerji Veri'!G:G),0) | E4: =IFERROR(AVERAGEIF('Opera Enerji Veri'!$C:$C,'Opera Günlük Analiz'!$B4,'Opera Enerji Veri'!H:H),0) | F4: =SUMIF('Opera Enerji Veri'!$C:$C, 'Opera Günlük Analiz'!$B4,'Opera Enerji Veri'!BE:BE) | G4: =SUMIF('Opera Enerji Veri'!$C:$C, 'Opera Günlük Analiz'!$B4,'Opera Enerji Veri'!AY:AY) | H4: =IFERROR(F4/G4,0) | I4: =SUMIF('Opera Enerji Veri'!$C:$C, 'Opera Günlük Analiz'!$B4,'Opera Enerji Veri'!J:J) | J4: =SUMIF('Opera Enerji Veri'!$C:$C, 'Opera Günlük Analiz'!$B4,'Opera Enerji Veri'!BF:BF) | K4: =SUMIF('Opera Enerji Veri'!$C:$C, 'Opera Günlük Analiz'!$B4,'Opera Enerji Veri'!BG:BG) | L4: =SUMIF('Opera Enerji Veri'!$C:$C, 'Opera Günlük Analiz'!$B4,'Opera Enerji Veri'!BH:BH) | M4: =SUMIF('Opera Enerji Veri'!$C:$C, 'Opera Günlük Analiz'!$B4,'Opera Enerji Veri'!BB:BB) | N4: =SUMIF('Opera Enerji Veri'!$C:$C, 'Opera Günlük Analiz'!$B4,'Opera Enerji Veri'!BJ:BJ) | O4: =SUMIF('Opera Enerji Veri'!$C:$C, 'Opera Günlük Analiz'!$B4,'Opera Enerji Veri'!BK:BK) | P4: =SUMIF('Opera Enerji Veri'!$C:$C, 'Opera Günlük Analiz'!$B4,'Opera Enerji Veri'!BL:BL) | Q4: =J4+K4+P4-M4 | R4: =F4-Q4-M4 | S4: =M4+R4 | T4: =IFERROR(Q4/G4,0) | U4: =IF(G4=0,0,S4/G4) | V4: =IFERROR(U4/H4,0) | W4: =IFERROR(ABS(N4/G4),0) | X4: =SUMIF('Opera Enerji Veri'!$C:$C, 'Opera Günlük Analiz'!$B4,'Opera Enerji Veri'!BU:BU) | Y4: =SUMIF('Opera Enerji Veri'!$C:$C, 'Opera Günlük Analiz'!$B4,'Opera Enerji Veri'!BD:BD) | Z4: =SUMIF('Opera Enerji Veri'!$C:$C, 'Opera Günlük Analiz'!$B4,'Opera Enerji Veri'!BW:BW) | AA4: =SUMIF('Opera Enerji Veri'!$C:$C, 'Opera Günlük Analiz'!$B4,'Opera Enerji Veri'!BX:BX) | AB4: =SUMIF('Opera Enerji Veri'!$C:$C, 'Opera Günlük Analiz'!$B4,'Opera Enerji Veri'!BY:BY) | AC4: =SUMIF('Opera Enerji Veri'!$C:$C, 'Opera Günlük Analiz'!$B4,'Opera Enerji Veri'!CI:CI) | AD4: =IFERROR(AC4/G4,0) | AE4: =J4+K4+L4+AB4-Y4 | AF4: =F4-AE4-Y4 | AG4: =Y4+AF4 | AH4: =IFERROR(AE4/G4,0) | AI4: =IF(G4=0,0,AG4/G4) | AJ4: =IFERROR(AI4/H4,0) | AK4: =IFERROR(ABS(Z4/G4),0) | AL4: =SUMIF('Opera Enerji Veri'!$C:$C, 'Opera Günlük Analiz'!$B4,'Opera Enerji Veri'!CH:CH) | AM4: =M4-Y4 | AN4: =IFERROR(AM4/M4,0) | AO4: =S4-AG4 | AP4: =IFERROR(AO4/S4,0)
B5: =B4+1 | C5: =IFERROR(AVERAGEIF('Opera Enerji Veri'!C:C,'Opera Günlük Analiz'!B5,'Opera Enerji Veri'!F:F),0) | D5: =IFERROR(AVERAGEIF('Opera Enerji Veri'!$C:$C,'Opera Günlük Analiz'!$B5,'Opera Enerji Veri'!G:G),0) | E5: =IFERROR(AVERAGEIF('Opera Enerji Veri'!$C:$C,'Opera Günlük Analiz'!$B5,'Opera Enerji Veri'!H:H),0) | F5: =SUMIF('Opera Enerji Veri'!$C:$C, 'Opera Günlük Analiz'!$B5,'Opera Enerji Veri'!BE:BE) | G5: =SUMIF('Opera Enerji Veri'!$C:$C, 'Opera Günlük Analiz'!$B5,'Opera Enerji Veri'!AY:AY) | H5: =IFERROR(F5/G5,0) | I5: =SUMIF('Opera Enerji Veri'!$C:$C, 'Opera Günlük Analiz'!$B5,'Opera Enerji Veri'!J:J) | J5: =SUMIF('Opera Enerji Veri'!$C:$C, 'Opera Günlük Analiz'!$B5,'Opera Enerji Veri'!BF:BF) | K5: =SUMIF('Opera Enerji Veri'!$C:$C, 'Opera Günlük Analiz'!$B5,'Opera Enerji Veri'!BG:BG) | L5: =SUMIF('Opera Enerji Veri'!$C:$C, 'Opera Günlük Analiz'!$B5,'Opera Enerji Veri'!BH:BH) | M5: =SUMIF('Opera Enerji Veri'!$C:$C, 'Opera Günlük Analiz'!$B5,'Opera Enerji Veri'!BB:BB) | N5: =SUMIF('Opera Enerji Veri'!$C:$C, 'Opera Günlük Analiz'!$B5,'Opera Enerji Veri'!BJ:BJ) | O5: =SUMIF('Opera Enerji Veri'!$C:$C, 'Opera Günlük Analiz'!$B5,'Opera Enerji Veri'!BK:BK) | P5: =SUMIF('Opera Enerji Veri'!$C:$C, 'Opera Günlük Analiz'!$B5,'Opera Enerji Veri'!BL:BL) | Q5: =J5+K5+P5-M5 | R5: =F5-Q5-M5 | S5: =M5+R5 | T5: =IFERROR(Q5/G5,0) | U5: =IF(G5=0,0,S5/G5) | V5: =IFERROR(U5/H5,0) | W5: =IFERROR(ABS(N5/G5),0) | X5: =SUMIF('Opera Enerji Veri'!$C:$C, 'Opera Günlük Analiz'!$B5,'Opera Enerji Veri'!BU:BU) | Y5: =SUMIF('Opera Enerji Veri'!$C:$C, 'Opera Günlük Analiz'!$B5,'Opera Enerji Veri'!BD:BD) | Z5: =SUMIF('Opera Enerji Veri'!$C:$C, 'Opera Günlük Analiz'!$B5,'Opera Enerji Veri'!BW:BW) | AA5: =SUMIF('Opera Enerji Veri'!$C:$C, 'Opera Günlük Analiz'!$B5,'Opera Enerji Veri'!BX:BX) | AB5: =SUMIF('Opera Enerji Veri'!$C:$C, 'Opera Günlük Analiz'!$B5,'Opera Enerji Veri'!BY:BY) | AC5: =SUMIF('Opera Enerji Veri'!$C:$C, 'Opera Günlük Analiz'!$B5,'Opera Enerji Veri'!CI:CI) | AD5: =IFERROR(AC5/G5,0) | AE5: =J5+K5+L5+AB5-Y5 | AF5: =F5-AE5-Y5 | AG5: =Y5+AF5 | AH5: =IFERROR(AE5/G5,0) | AI5: =IF(G5=0,0,AG5/G5) | AJ5: =IFERROR(AI5/H5,0) | AK5: =IFERROR(ABS(Z5/G5),0) | AL5: =SUMIF('Opera Enerji Veri'!$C:$C, 'Opera Günlük Analiz'!$B5,'Opera Enerji Veri'!CH:CH) | AM5: =M5-Y5 | AN5: =IFERROR(AM5/M5,0) | AO5: =S5-AG5 | AP5: =IFERROR(AO5/S5,0)
B6: =B5+1 | C6: =IFERROR(AVERAGEIF('Opera Enerji Veri'!C:C,'Opera Günlük Analiz'!B6,'Opera Enerji Veri'!F:F),0) | D6: =IFERROR(AVERAGEIF('Opera Enerji Veri'!$C:$C,'Opera Günlük Analiz'!$B6,'Opera Enerji Veri'!G:G),0) | E6: =IFERROR(AVERAGEIF('Opera Enerji Veri'!$C:$C,'Opera Günlük Analiz'!$B6,'Opera Enerji Veri'!H:H),0) | F6: =SUMIF('Opera Enerji Veri'!$C:$C, 'Opera Günlük Analiz'!$B6,'Opera Enerji Veri'!BE:BE) | G6: =SUMIF('Opera Enerji Veri'!$C:$C, 'Opera Günlük Analiz'!$B6,'Opera Enerji Veri'!AY:AY) | H6: =IFERROR(F6/G6,0) | I6: =SUMIF('Opera Enerji Veri'!$C:$C, 'Opera Günlük Analiz'!$B6,'Opera Enerji Veri'!J:J) | J6: =SUMIF('Opera Enerji Veri'!$C:$C, 'Opera Günlük Analiz'!$B6,'Opera Enerji Veri'!BF:BF) | K6: =SUMIF('Opera Enerji Veri'!$C:$C, 'Opera Günlük Analiz'!$B6,'Opera Enerji Veri'!BG:BG) | L6: =SUMIF('Opera Enerji Veri'!$C:$C, 'Opera Günlük Analiz'!$B6,'Opera Enerji Veri'!BH:BH) | M6: =SUMIF('Opera Enerji Veri'!$C:$C, 'Opera Günlük Analiz'!$B6,'Opera Enerji Veri'!BB:BB) | N6: =SUMIF('Opera Enerji Veri'!$C:$C, 'Opera Günlük Analiz'!$B6,'Opera Enerji Veri'!BJ:BJ) | O6: =SUMIF('Opera Enerji Veri'!$C:$C, 'Opera Günlük Analiz'!$B6,'Opera Enerji Veri'!BK:BK) | P6: =SUMIF('Opera Enerji Veri'!$C:$C, 'Opera Günlük Analiz'!$B6,'Opera Enerji Veri'!BL:BL) | Q6: =J6+K6+P6-M6 | R6: =F6-Q6-M6 | S6: =M6+R6 | T6: =IFERROR(Q6/G6,0) | U6: =IF(G6=0,0,S6/G6) | V6: =IFERROR(U6/H6,0) | W6: =IFERROR(ABS(N6/G6),0) | X6: =SUMIF('Opera Enerji Veri'!$C:$C, 'Opera Günlük Analiz'!$B6,'Opera Enerji Veri'!BU:BU) | Y6: =SUMIF('Opera Enerji Veri'!$C:$C, 'Opera Günlük Analiz'!$B6,'Opera Enerji Veri'!BD:BD) | Z6: =SUMIF('Opera Enerji Veri'!$C:$C, 'Opera Günlük Analiz'!$B6,'Opera Enerji Veri'!BW:BW) | AA6: =SUMIF('Opera Enerji Veri'!$C:$C, 'Opera Günlük Analiz'!$B6,'Opera Enerji Veri'!BX:BX) | AB6: =SUMIF('Opera Enerji Veri'!$C:$C, 'Opera Günlük Analiz'!$B6,'Opera Enerji Veri'!BY:BY) | AC6: =SUMIF('Opera Enerji Veri'!$C:$C, 'Opera Günlük Analiz'!$B6,'Opera Enerji Veri'!CI:CI) | AD6: =IFERROR(AC6/G6,0) | AE6: =J6+K6+L6+AB6-Y6 | AF6: =F6-AE6-Y6 | AG6: =Y6+AF6 | AH6: =IFERROR(AE6/G6,0) | AI6: =IF(G6=0,0,AG6/G6) | AJ6: =IFERROR(AI6/H6,0) | AK6: =IFERROR(ABS(Z6/G6),0) | AL6: =SUMIF('Opera Enerji Veri'!$C:$C, 'Opera Günlük Analiz'!$B6,'Opera Enerji Veri'!CH:CH) | AM6: =M6-Y6 | AN6: =IFERROR(AM6/M6,0) | AO6: =S6-AG6 | AP6: =IFERROR(AO6/S6,0)
B7: =B6+1 | C7: =IFERROR(AVERAGEIF('Opera Enerji Veri'!C:C,'Opera Günlük Analiz'!B7,'Opera Enerji Veri'!F:F),0) | D7: =IFERROR(AVERAGEIF('Opera Enerji Veri'!$C:$C,'Opera Günlük Analiz'!$B7,'Opera Enerji Veri'!G:G),0) | E7: =IFERROR(AVERAGEIF('Opera Enerji Veri'!$C:$C,'Opera Günlük Analiz'!$B7,'Opera Enerji Veri'!H:H),0) | F7: =SUMIF('Opera Enerji Veri'!$C:$C, 'Opera Günlük Analiz'!$B7,'Opera Enerji Veri'!BE:BE) | G7: =SUMIF('Opera Enerji Veri'!$C:$C, 'Opera Günlük Analiz'!$B7,'Opera Enerji Veri'!AY:AY) | H7: =IFERROR(F7/G7,0) | I7: =SUMIF('Opera Enerji Veri'!$C:$C, 'Opera Günlük Analiz'!$B7,'Opera Enerji Veri'!J:J) | J7: =SUMIF('Opera Enerji Veri'!$C:$C, 'Opera Günlük Analiz'!$B7,'Opera Enerji Veri'!BF:BF) | K7: =SUMIF('Opera Enerji Veri'!$C:$C, 'Opera Günlük Analiz'!$B7,'Opera Enerji Veri'!BG:BG) | L7: =SUMIF('Opera Enerji Veri'!$C:$C, 'Opera Günlük Analiz'!$B7,'Opera Enerji Veri'!BH:BH) | M7: =SUMIF('Opera Enerji Veri'!$C:$C, 'Opera Günlük Analiz'!$B7,'Opera Enerji Veri'!BB:BB) | N7: =SUMIF('Opera Enerji Veri'!$C:$C, 'Opera Günlük Analiz'!$B7,'Opera Enerji Veri'!BJ:BJ) | O7: =SUMIF('Opera Enerji Veri'!$C:$C, 'Opera Günlük Analiz'!$B7,'Opera Enerji Veri'!BK:BK) | P7: =SUMIF('Opera Enerji Veri'!$C:$C, 'Opera Günlük Analiz'!$B7,'Opera Enerji Veri'!BL:BL) | Q7: =J7+K7+P7-M7 | R7: =F7-Q7-M7 | S7: =M7+R7 | T7: =IFERROR(Q7/G7,0) | U7: =IF(G7=0,0,S7/G7) | V7: =IFERROR(U7/H7,0) | W7: =IFERROR(ABS(N7/G7),0) | X7: =SUMIF('Opera Enerji Veri'!$C:$C, 'Opera Günlük Analiz'!$B7,'Opera Enerji Veri'!BU:BU) | Y7: =SUMIF('Opera Enerji Veri'!$C:$C, 'Opera Günlük Analiz'!$B7,'Opera Enerji Veri'!BD:BD) | Z7: =SUMIF('Opera Enerji Veri'!$C:$C, 'Opera Günlük Analiz'!$B7,'Opera Enerji Veri'!BW:BW) | AA7: =SUMIF('Opera Enerji Veri'!$C:$C, 'Opera Günlük Analiz'!$B7,'Opera Enerji Veri'!BX:BX) | AB7: =SUMIF('Opera Enerji Veri'!$C:$C, 'Opera Günlük Analiz'!$B7,'Opera Enerji Veri'!BY:BY) | AC7: =SUMIF('Opera Enerji Veri'!$C:$C, 'Opera Günlük Analiz'!$B7,'Opera Enerji Veri'!CI:CI) | AD7: =IFERROR(AC7/G7,0) | AE7: =J7+K7+L7+AB7-Y7 | AF7: =F7-AE7-Y7 | AG7: =Y7+AF7 | AH7: =IFERROR(AE7/G7,0) | AI7: =IF(G7=0,0,AG7/G7) | AJ7: =IFERROR(AI7/H7,0) | AK7: =IFERROR(ABS(Z7/G7),0) | AL7: =SUMIF('Opera Enerji Veri'!$C:$C, 'Opera Günlük Analiz'!$B7,'Opera Enerji Veri'!CH:CH) | AM7: =M7-Y7 | AN7: =IFERROR(AM7/M7,0) | AO7: =S7-AG7 | AP7: =IFERROR(AO7/S7,0)
B8: =B7+1 | C8: =IFERROR(AVERAGEIF('Opera Enerji Veri'!C:C,'Opera Günlük Analiz'!B8,'Opera Enerji Veri'!F:F),0) | D8: =IFERROR(AVERAGEIF('Opera Enerji Veri'!$C:$C,'Opera Günlük Analiz'!$B8,'Opera Enerji Veri'!G:G),0) | E8: =IFERROR(AVERAGEIF('Opera Enerji Veri'!$C:$C,'Opera Günlük Analiz'!$B8,'Opera Enerji Veri'!H:H),0) | F8: =SUMIF('Opera Enerji Veri'!$C:$C, 'Opera Günlük Analiz'!$B8,'Opera Enerji Veri'!BE:BE) | G8: =SUMIF('Opera Enerji Veri'!$C:$C, 'Opera Günlük Analiz'!$B8,'Opera Enerji Veri'!AY:AY) | H8: =IFERROR(F8/G8,0) | I8: =SUMIF('Opera Enerji Veri'!$C:$C, 'Opera Günlük Analiz'!$B8,'Opera Enerji Veri'!J:J) | J8: =SUMIF('Opera Enerji Veri'!$C:$C, 'Opera Günlük Analiz'!$B8,'Opera Enerji Veri'!BF:BF) | K8: =SUMIF('Opera Enerji Veri'!$C:$C, 'Opera Günlük Analiz'!$B8,'Opera Enerji Veri'!BG:BG) | L8: =SUMIF('Opera Enerji Veri'!$C:$C, 'Opera Günlük Analiz'!$B8,'Opera Enerji Veri'!BH:BH) | M8: =SUMIF('Opera Enerji Veri'!$C:$C, 'Opera Günlük Analiz'!$B8,'Opera Enerji Veri'!BB:BB) | N8: =SUMIF('Opera Enerji Veri'!$C:$C, 'Opera Günlük Analiz'!$B8,'Opera Enerji Veri'!BJ:BJ) | O8: =SUMIF('Opera Enerji Veri'!$C:$C, 'Opera Günlük Analiz'!$B8,'Opera Enerji Veri'!BK:BK) | P8: =SUMIF('Opera Enerji Veri'!$C:$C, 'Opera Günlük Analiz'!$B8,'Opera Enerji Veri'!BL:BL) | Q8: =J8+K8+P8-M8 | R8: =F8-Q8-M8 | S8: =M8+R8 | T8: =IFERROR(Q8/G8,0) | U8: =IF(G8=0,0,S8/G8) | V8: =IFERROR(U8/H8,0) | W8: =IFERROR(ABS(N8/G8),0) | X8: =SUMIF('Opera Enerji Veri'!$C:$C, 'Opera Günlük Analiz'!$B8,'Opera Enerji Veri'!BU:BU) | Y8: =SUMIF('Opera Enerji Veri'!$C:$C, 'Opera Günlük Analiz'!$B8,'Opera Enerji Veri'!BD:BD) | Z8: =SUMIF('Opera Enerji Veri'!$C:$C, 'Opera Günlük Analiz'!$B8,'Opera Enerji Veri'!BW:BW) | AA8: =SUMIF('Opera Enerji Veri'!$C:$C, 'Opera Günlük Analiz'!$B8,'Opera Enerji Veri'!BX:BX) | AB8: =SUMIF('Opera Enerji Veri'!$C:$C, 'Opera Günlük Analiz'!$B8,'Opera Enerji Veri'!BY:BY) | AC8: =SUMIF('Opera Enerji Veri'!$C:$C, 'Opera Günlük Analiz'!$B8,'Opera Enerji Veri'!CI:CI) | AD8: =IFERROR(AC8/G8,0) | AE8: =J8+K8+L8+AB8-Y8 | AF8: =F8-AE8-Y8 | AG8: =Y8+AF8 | AH8: =IFERROR(AE8/G8,0) | AI8: =IF(G8=0,0,AG8/G8) | AJ8: =IFERROR(AI8/H8,0) | AK8: =IFERROR(ABS(Z8/G8),0) | AL8: =SUMIF('Opera Enerji Veri'!$C:$C, 'Opera Günlük Analiz'!$B8,'Opera Enerji Veri'!CH:CH) | AM8: =M8-Y8 | AN8: =IFERROR(AM8/M8,0) | AO8: =S8-AG8 | AP8: =IFERROR(AO8/S8,0)
B9: =B8+1 | C9: =IFERROR(AVERAGEIF('Opera Enerji Veri'!C:C,'Opera Günlük Analiz'!B9,'Opera Enerji Veri'!F:F),0) | D9: =IFERROR(AVERAGEIF('Opera Enerji Veri'!$C:$C,'Opera Günlük Analiz'!$B9,'Opera Enerji Veri'!G:G),0) | E9: =IFERROR(AVERAGEIF('Opera Enerji Veri'!$C:$C,'Opera Günlük Analiz'!$B9,'Opera Enerji Veri'!H:H),0) | F9: =SUMIF('Opera Enerji Veri'!$C:$C, 'Opera Günlük Analiz'!$B9,'Opera Enerji Veri'!BE:BE) | G9: =SUMIF('Opera Enerji Veri'!$C:$C, 'Opera Günlük Analiz'!$B9,'Opera Enerji Veri'!AY:AY) | H9: =IFERROR(F9/G9,0) | I9: =SUMIF('Opera Enerji Veri'!$C:$C, 'Opera Günlük Analiz'!$B9,'Opera Enerji Veri'!J:J) | J9: =SUMIF('Opera Enerji Veri'!$C:$C, 'Opera Günlük Analiz'!$B9,'Opera Enerji Veri'!BF:BF) | K9: =SUMIF('Opera Enerji Veri'!$C:$C, 'Opera Günlük Analiz'!$B9,'Opera Enerji Veri'!BG:BG) | L9: =SUMIF('Opera Enerji Veri'!$C:$C, 'Opera Günlük Analiz'!$B9,'Opera Enerji Veri'!BH:BH) | M9: =SUMIF('Opera Enerji Veri'!$C:$C, 'Opera Günlük Analiz'!$B9,'Opera Enerji Veri'!BB:BB) | N9: =SUMIF('Opera Enerji Veri'!$C:$C, 'Opera Günlük Analiz'!$B9,'Opera Enerji Veri'!BJ:BJ) | O9: =SUMIF('Opera Enerji Veri'!$C:$C, 'Opera Günlük Analiz'!$B9,'Opera Enerji Veri'!BK:BK) | P9: =SUMIF('Opera Enerji Veri'!$C:$C, 'Opera Günlük Analiz'!$B9,'Opera Enerji Veri'!BL:BL) | Q9: =J9+K9+P9-M9 | R9: =F9-Q9-M9 | S9: =M9+R9 | T9: =IFERROR(Q9/G9,0) | U9: =IF(G9=0,0,S9/G9) | V9: =IFERROR(U9/H9,0) | W9: =IFERROR(ABS(N9/G9),0) | X9: =SUMIF('Opera Enerji Veri'!$C:$C, 'Opera Günlük Analiz'!$B9,'Opera Enerji Veri'!BU:BU) | Y9: =SUMIF('Opera Enerji Veri'!$C:$C, 'Opera Günlük Analiz'!$B9,'Opera Enerji Veri'!BD:BD) | Z9: =SUMIF('Opera Enerji Veri'!$C:$C, 'Opera Günlük Analiz'!$B9,'Opera Enerji Veri'!BW:BW) | AA9: =SUMIF('Opera Enerji Veri'!$C:$C, 'Opera Günlük Analiz'!$B9,'Opera Enerji Veri'!BX:BX) | AB9: =SUMIF('Opera Enerji Veri'!$C:$C, 'Opera Günlük Analiz'!$B9,'Opera Enerji Veri'!BY:BY) | AC9: =SUMIF('Opera Enerji Veri'!$C:$C, 'Opera Günlük Analiz'!$B9,'Opera Enerji Veri'!CI:CI) | AD9: =IFERROR(AC9/G9,0) | AE9: =J9+K9+L9+AB9-Y9 | AF9: =F9-AE9-Y9 | AG9: =Y9+AF9 | AH9: =IFERROR(AE9/G9,0) | AI9: =IF(G9=0,0,AG9/G9) | AJ9: =IFERROR(AI9/H9,0) | AK9: =IFERROR(ABS(Z9/G9),0) | AL9: =SUMIF('Opera Enerji Veri'!$C:$C, 'Opera Günlük Analiz'!$B9,'Opera Enerji Veri'!CH:CH) | AM9: =M9-Y9 | AN9: =IFERROR(AM9/M9,0) | AO9: =S9-AG9 | AP9: =IFERROR(AO9/S9,0)
B10: =B9+1 | C10: =IFERROR(AVERAGEIF('Opera Enerji Veri'!C:C,'Opera Günlük Analiz'!B10,'Opera Enerji Veri'!F:F),0) | D10: =IFERROR(AVERAGEIF('Opera Enerji Veri'!$C:$C,'Opera Günlük Analiz'!$B10,'Opera Enerji Veri'!G:G),0) | E10: =IFERROR(AVERAGEIF('Opera Enerji Veri'!$C:$C,'Opera Günlük Analiz'!$B10,'Opera Enerji Veri'!H:H),0) | F10: =SUMIF('Opera Enerji Veri'!$C:$C, 'Opera Günlük Analiz'!$B10,'Opera Enerji Veri'!BE:BE) | G10: =SUMIF('Opera Enerji Veri'!$C:$C, 'Opera Günlük Analiz'!$B10,'Opera Enerji Veri'!AY:AY) | H10: =IFERROR(F10/G10,0) | I10: =SUMIF('Opera Enerji Veri'!$C:$C, 'Opera Günlük Analiz'!$B10,'Opera Enerji Veri'!J:J) | J10: =SUMIF('Opera Enerji Veri'!$C:$C, 'Opera Günlük Analiz'!$B10,'Opera Enerji Veri'!BF:BF) | K10: =SUMIF('Opera Enerji Veri'!$C:$C, 'Opera Günlük Analiz'!$B10,'Opera Enerji Veri'!BG:BG) | L10: =SUMIF('Opera Enerji Veri'!$C:$C, 'Opera Günlük Analiz'!$B10,'Opera Enerji Veri'!BH:BH) | M10: =SUMIF('Opera Enerji Veri'!$C:$C, 'Opera Günlük Analiz'!$B10,'Opera Enerji Veri'!BB:BB) | N10: =SUMIF('Opera Enerji Veri'!$C:$C, 'Opera Günlük Analiz'!$B10,'Opera Enerji Veri'!BJ:BJ) | O10: =SUMIF('Opera Enerji Veri'!$C:$C, 'Opera Günlük Analiz'!$B10,'Opera Enerji Veri'!BK:BK) | P10: =SUMIF('Opera Enerji Veri'!$C:$C, 'Opera Günlük Analiz'!$B10,'Opera Enerji Veri'!BL:BL) | Q10: =J10+K10+P10-M10 | R10: =F10-Q10-M10 | S10: =M10+R10 | T10: =IFERROR(Q10/G10,0) | U10: =IF(G10=0,0,S10/G10) | V10: =IFERROR(U10/H10,0) | W10: =IFERROR(ABS(N10/G10),0) | X10: =SUMIF('Opera Enerji Veri'!$C:$C, 'Opera Günlük Analiz'!$B10,'Opera Enerji Veri'!BU:BU) | Y10: =SUMIF('Opera Enerji Veri'!$C:$C, 'Opera Günlük Analiz'!$B10,'Opera Enerji Veri'!BD:BD) | Z10: =SUMIF('Opera Enerji Veri'!$C:$C, 'Opera Günlük Analiz'!$B10,'Opera Enerji Veri'!BW:BW) | AA10: =SUMIF('Opera Enerji Veri'!$C:$C, 'Opera Günlük Analiz'!$B10,'Opera Enerji Veri'!BX:BX) | AB10: =SUMIF('Opera Enerji Veri'!$C:$C, 'Opera Günlük Analiz'!$B10,'Opera Enerji Veri'!BY:BY) | AC10: =SUMIF('Opera Enerji Veri'!$C:$C, 'Opera Günlük Analiz'!$B10,'Opera Enerji Veri'!CI:CI) | AD10: =IFERROR(AC10/G10,0) | AE10: =J10+K10+L10+AB10-Y10 | AF10: =F10-AE10-Y10 | AG10: =Y10+AF10 | AH10: =IFERROR(AE10/G10,0) | AI10: =IF(G10=0,0,AG10/G10) | AJ10: =IFERROR(AI10/H10,0) | AK10: =IFERROR(ABS(Z10/G10),0) | AL10: =SUMIF('Opera Enerji Veri'!$C:$C, 'Opera Günlük Analiz'!$B10,'Opera Enerji Veri'!CH:CH) | AM10: =M10-Y10 | AN10: =IFERROR(AM10/M10,0) | AO10: =S10-AG10 | AP10: =IFERROR(AO10/S10,0)
B11: =B10+1 | C11: =IFERROR(AVERAGEIF('Opera Enerji Veri'!C:C,'Opera Günlük Analiz'!B11,'Opera Enerji Veri'!F:F),0) | D11: =IFERROR(AVERAGEIF('Opera Enerji Veri'!$C:$C,'Opera Günlük Analiz'!$B11,'Opera Enerji Veri'!G:G),0) | E11: =IFERROR(AVERAGEIF('Opera Enerji Veri'!$C:$C,'Opera Günlük Analiz'!$B11,'Opera Enerji Veri'!H:H),0) | F11: =SUMIF('Opera Enerji Veri'!$C:$C, 'Opera Günlük Analiz'!$B11,'Opera Enerji Veri'!BE:BE) | G11: =SUMIF('Opera Enerji Veri'!$C:$C, 'Opera Günlük Analiz'!$B11,'Opera Enerji Veri'!AY:AY) | H11: =IFERROR(F11/G11,0) | I11: =SUMIF('Opera Enerji Veri'!$C:$C, 'Opera Günlük Analiz'!$B11,'Opera Enerji Veri'!J:J) | J11: =SUMIF('Opera Enerji Veri'!$C:$C, 'Opera Günlük Analiz'!$B11,'Opera Enerji Veri'!BF:BF) | K11: =SUMIF('Opera Enerji Veri'!$C:$C, 'Opera Günlük Analiz'!$B11,'Opera Enerji Veri'!BG:BG) | L11: =SUMIF('Opera Enerji Veri'!$C:$C, 'Opera Günlük Analiz'!$B11,'Opera Enerji Veri'!BH:BH) | M11: =SUMIF('Opera Enerji Veri'!$C:$C, 'Opera Günlük Analiz'!$B11,'Opera Enerji Veri'!BB:BB) | N11: =SUMIF('Opera Enerji Veri'!$C:$C, 'Opera Günlük Analiz'!$B11,'Opera Enerji Veri'!BJ:BJ) | O11: =SUMIF('Opera Enerji Veri'!$C:$C, 'Opera Günlük Analiz'!$B11,'Opera Enerji Veri'!BK:BK) | P11: =SUMIF('Opera Enerji Veri'!$C:$C, 'Opera Günlük Analiz'!$B11,'Opera Enerji Veri'!BL:BL) | Q11: =J11+K11+P11-M11 | R11: =F11-Q11-M11 | S11: =M11+R11 | T11: =IFERROR(Q11/G11,0) | U11: =IF(G11=0,0,S11/G11) | V11: =IFERROR(U11/H11,0) | W11: =IFERROR(ABS(N11/G11),0) | X11: =SUMIF('Opera Enerji Veri'!$C:$C, 'Opera Günlük Analiz'!$B11,'Opera Enerji Veri'!BU:BU) | Y11: =SUMIF('Opera Enerji Veri'!$C:$C, 'Opera Günlük Analiz'!$B11,'Opera Enerji Veri'!BD:BD) | Z11: =SUMIF('Opera Enerji Veri'!$C:$C, 'Opera Günlük Analiz'!$B11,'Opera Enerji Veri'!BW:BW) | AA11: =SUMIF('Opera Enerji Veri'!$C:$C, 'Opera Günlük Analiz'!$B11,'Opera Enerji Veri'!BX:BX) | AB11: =SUMIF('Opera Enerji Veri'!$C:$C, 'Opera Günlük Analiz'!$B11,'Opera Enerji Veri'!BY:BY) | AC11: =SUMIF('Opera Enerji Veri'!$C:$C, 'Opera Günlük Analiz'!$B11,'Opera Enerji Veri'!CI:CI) | AD11: =IFERROR(AC11/G11,0) | AE11: =J11+K11+L11+AB11-Y11 | AF11: =F11-AE11-Y11 | AG11: =Y11+AF11 | AH11: =IFERROR(AE11/G11,0) | AI11: =IF(G11=0,0,AG11/G11) | AJ11: =IFERROR(AI11/H11,0) | AK11: =IFERROR(ABS(Z11/G11),0) | AL11: =SUMIF('Opera Enerji Veri'!$C:$C, 'Opera Günlük Analiz'!$B11,'Opera Enerji Veri'!CH:CH) | AM11: =M11-Y11 | AN11: =IFERROR(AM11/M11,0) | AO11: =S11-AG11 | AP11: =IFERROR(AO11/S11,0)
B12: =B11+1 | C12: =IFERROR(AVERAGEIF('Opera Enerji Veri'!C:C,'Opera Günlük Analiz'!B12,'Opera Enerji Veri'!F:F),0) | D12: =IFERROR(AVERAGEIF('Opera Enerji Veri'!$C:$C,'Opera Günlük Analiz'!$B12,'Opera Enerji Veri'!G:G),0) | E12: =IFERROR(AVERAGEIF('Opera Enerji Veri'!$C:$C,'Opera Günlük Analiz'!$B12,'Opera Enerji Veri'!H:H),0) | F12: =SUMIF('Opera Enerji Veri'!$C:$C, 'Opera Günlük Analiz'!$B12,'Opera Enerji Veri'!BE:BE) | G12: =SUMIF('Opera Enerji Veri'!$C:$C, 'Opera Günlük Analiz'!$B12,'Opera Enerji Veri'!AY:AY) | H12: =IFERROR(F12/G12,0) | I12: =SUMIF('Opera Enerji Veri'!$C:$C, 'Opera Günlük Analiz'!$B12,'Opera Enerji Veri'!J:J) | J12: =SUMIF('Opera Enerji Veri'!$C:$C, 'Opera Günlük Analiz'!$B12,'Opera Enerji Veri'!BF:BF) | K12: =SUMIF('Opera Enerji Veri'!$C:$C, 'Opera Günlük Analiz'!$B12,'Opera Enerji Veri'!BG:BG) | L12: =SUMIF('Opera Enerji Veri'!$C:$C, 'Opera Günlük Analiz'!$B12,'Opera Enerji Veri'!BH:BH) | M12: =SUMIF('Opera Enerji Veri'!$C:$C, 'Opera Günlük Analiz'!$B12,'Opera Enerji Veri'!BB:BB) | N12: =SUMIF('Opera Enerji Veri'!$C:$C, 'Opera Günlük Analiz'!$B12,'Opera Enerji Veri'!BJ:BJ) | O12: =SUMIF('Opera Enerji Veri'!$C:$C, 'Opera Günlük Analiz'!$B12,'Opera Enerji Veri'!BK:BK) | P12: =SUMIF('Opera Enerji Veri'!$C:$C, 'Opera Günlük Analiz'!$B12,'Opera Enerji Veri'!BL:BL) | Q12: =J12+K12+P12-M12 | R12: =F12-Q12-M12 | S12: =M12+R12 | T12: =IFERROR(Q12/G12,0) | U12: =IF(G12=0,0,S12/G12) | V12: =IFERROR(U12/H12,0) | W12: =IFERROR(ABS(N12/G12),0) | X12: =SUMIF('Opera Enerji Veri'!$C:$C, 'Opera Günlük Analiz'!$B12,'Opera Enerji Veri'!BU:BU) | Y12: =SUMIF('Opera Enerji Veri'!$C:$C, 'Opera Günlük Analiz'!$B12,'Opera Enerji Veri'!BD:BD) | Z12: =SUMIF('Opera Enerji Veri'!$C:$C, 'Opera Günlük Analiz'!$B12,'Opera Enerji Veri'!BW:BW) | AA12: =SUMIF('Opera Enerji Veri'!$C:$C, 'Opera Günlük Analiz'!$B12,'Opera Enerji Veri'!BX:BX) | AB12: =SUMIF('Opera Enerji Veri'!$C:$C, 'Opera Günlük Analiz'!$B12,'Opera Enerji Veri'!BY:BY) | AC12: =SUMIF('Opera Enerji Veri'!$C:$C, 'Opera Günlük Analiz'!$B12,'Opera Enerji Veri'!CI:CI) | AD12: =IFERROR(AC12/G12,0) | AE12: =J12+K12+L12+AB12-Y12 | AF12: =F12-AE12-Y12 | AG12: =Y12+AF12 | AH12: =IFERROR(AE12/G12,0) | AI12: =IF(G12=0,0,AG12/G12) | AJ12: =IFERROR(AI12/H12,0) | AK12: =IFERROR(ABS(Z12/G12),0) | AL12: =SUMIF('Opera Enerji Veri'!$C:$C, 'Opera Günlük Analiz'!$B12,'Opera Enerji Veri'!CH:CH) | AM12: =M12-Y12 | AN12: =IFERROR(AM12/M12,0) | AO12: =S12-AG12 | AP12: =IFERROR(AO12/S12,0)
B13: =B12+1 | C13: =IFERROR(AVERAGEIF('Opera Enerji Veri'!C:C,'Opera Günlük Analiz'!B13,'Opera Enerji Veri'!F:F),0) | D13: =IFERROR(AVERAGEIF('Opera Enerji Veri'!$C:$C,'Opera Günlük Analiz'!$B13,'Opera Enerji Veri'!G:G),0) | E13: =IFERROR(AVERAGEIF('Opera Enerji Veri'!$C:$C,'Opera Günlük Analiz'!$B13,'Opera Enerji Veri'!H:H),0) | F13: =SUMIF('Opera Enerji Veri'!$C:$C, 'Opera Günlük Analiz'!$B13,'Opera Enerji Veri'!BE:BE) | G13: =SUMIF('Opera Enerji Veri'!$C:$C, 'Opera Günlük Analiz'!$B13,'Opera Enerji Veri'!AY:AY) | H13: =IFERROR(F13/G13,0) | I13: =SUMIF('Opera Enerji Veri'!$C:$C, 'Opera Günlük Analiz'!$B13,'Opera Enerji Veri'!J:J) | J13: =SUMIF('Opera Enerji Veri'!$C:$C, 'Opera Günlük Analiz'!$B13,'Opera Enerji Veri'!BF:BF) | K13: =SUMIF('Opera Enerji Veri'!$C:$C, 'Opera Günlük Analiz'!$B13,'Opera Enerji Veri'!BG:BG) | L13: =SUMIF('Opera Enerji Veri'!$C:$C, 'Opera Günlük Analiz'!$B13,'Opera Enerji Veri'!BH:BH) | M13: =SUMIF('Opera Enerji Veri'!$C:$C, 'Opera Günlük Analiz'!$B13,'Opera Enerji Veri'!BB:BB) | N13: =SUMIF('Opera Enerji Veri'!$C:$C, 'Opera Günlük Analiz'!$B13,'Opera Enerji Veri'!BJ:BJ) | O13: =SUMIF('Opera Enerji Veri'!$C:$C, 'Opera Günlük Analiz'!$B13,'Opera Enerji Veri'!BK:BK) | P13: =SUMIF('Opera Enerji Veri'!$C:$C, 'Opera Günlük Analiz'!$B13,'Opera Enerji Veri'!BL:BL) | Q13: =J13+K13+P13-M13 | R13: =F13-Q13-M13 | S13: =M13+R13 | T13: =IFERROR(Q13/G13,0) | U13: =IF(G13=0,0,S13/G13) | V13: =IFERROR(U13/H13,0) | W13: =IFERROR(ABS(N13/G13),0) | X13: =SUMIF('Opera Enerji Veri'!$C:$C, 'Opera Günlük Analiz'!$B13,'Opera Enerji Veri'!BU:BU) | Y13: =SUMIF('Opera Enerji Veri'!$C:$C, 'Opera Günlük Analiz'!$B13,'Opera Enerji Veri'!BD:BD) | Z13: =SUMIF('Opera Enerji Veri'!$C:$C, 'Opera Günlük Analiz'!$B13,'Opera Enerji Veri'!BW:BW) | AA13: =SUMIF('Opera Enerji Veri'!$C:$C, 'Opera Günlük Analiz'!$B13,'Opera Enerji Veri'!BX:BX) | AB13: =SUMIF('Opera Enerji Veri'!$C:$C, 'Opera Günlük Analiz'!$B13,'Opera Enerji Veri'!BY:BY) | AC13: =SUMIF('Opera Enerji Veri'!$C:$C, 'Opera Günlük Analiz'!$B13,'Opera Enerji Veri'!CI:CI) | AD13: =IFERROR(AC13/G13,0) | AE13: =J13+K13+L13+AB13-Y13 | AF13: =F13-AE13-Y13 | AG13: =Y13+AF13 | AH13: =IFERROR(AE13/G13,0) | AI13: =IF(G13=0,0,AG13/G13) | AJ13: =IFERROR(AI13/H13,0) | AK13: =IFERROR(ABS(Z13/G13),0) | AL13: =SUMIF('Opera Enerji Veri'!$C:$C, 'Opera Günlük Analiz'!$B13,'Opera Enerji Veri'!CH:CH) | AM13: =M13-Y13 | AN13: =IFERROR(AM13/M13,0) | AO13: =S13-AG13 | AP13: =IFERROR(AO13/S13,0)
B14: =B13+1 | C14: =IFERROR(AVERAGEIF('Opera Enerji Veri'!C:C,'Opera Günlük Analiz'!B14,'Opera Enerji Veri'!F:F),0) | D14: =IFERROR(AVERAGEIF('Opera Enerji Veri'!$C:$C,'Opera Günlük Analiz'!$B14,'Opera Enerji Veri'!G:G),0) | E14: =IFERROR(AVERAGEIF('Opera Enerji Veri'!$C:$C,'Opera Günlük Analiz'!$B14,'Opera Enerji Veri'!H:H),0) | F14: =SUMIF('Opera Enerji Veri'!$C:$C, 'Opera Günlük Analiz'!$B14,'Opera Enerji Veri'!BE:BE) | G14: =SUMIF('Opera Enerji Veri'!$C:$C, 'Opera Günlük Analiz'!$B14,'Opera Enerji Veri'!AY:AY) | H14: =IFERROR(F14/G14,0) | I14: =SUMIF('Opera Enerji Veri'!$C:$C, 'Opera Günlük Analiz'!$B14,'Opera Enerji Veri'!J:J) | J14: =SUMIF('Opera Enerji Veri'!$C:$C, 'Opera Günlük Analiz'!$B14,'Opera Enerji Veri'!BF:BF) | K14: =SUMIF('Opera Enerji Veri'!$C:$C, 'Opera Günlük Analiz'!$B14,'Opera Enerji Veri'!BG:BG) | L14: =SUMIF('Opera Enerji Veri'!$C:$C, 'Opera Günlük Analiz'!$B14,'Opera Enerji Veri'!BH:BH) | M14: =SUMIF('Opera Enerji Veri'!$C:$C, 'Opera Günlük Analiz'!$B14,'Opera Enerji Veri'!BB:BB) | N14: =SUMIF('Opera Enerji Veri'!$C:$C, 'Opera Günlük Analiz'!$B14,'Opera Enerji Veri'!BJ:BJ) | O14: =SUMIF('Opera Enerji Veri'!$C:$C, 'Opera Günlük Analiz'!$B14,'Opera Enerji Veri'!BK:BK) | P14: =SUMIF('Opera Enerji Veri'!$C:$C, 'Opera Günlük Analiz'!$B14,'Opera Enerji Veri'!BL:BL) | Q14: =J14+K14+P14-M14 | R14: =F14-Q14-M14 | S14: =M14+R14 | T14: =IFERROR(Q14/G14,0) | U14: =IF(G14=0,0,S14/G14) | V14: =IFERROR(U14/H14,0) | W14: =IFERROR(ABS(N14/G14),0) | X14: =SUMIF('Opera Enerji Veri'!$C:$C, 'Opera Günlük Analiz'!$B14,'Opera Enerji Veri'!BU:BU) | Y14: =SUMIF('Opera Enerji Veri'!$C:$C, 'Opera Günlük Analiz'!$B14,'Opera Enerji Veri'!BD:BD) | Z14: =SUMIF('Opera Enerji Veri'!$C:$C, 'Opera Günlük Analiz'!$B14,'Opera Enerji Veri'!BW:BW) | AA14: =SUMIF('Opera Enerji Veri'!$C:$C, 'Opera Günlük Analiz'!$B14,'Opera Enerji Veri'!BX:BX) | AB14: =SUMIF('Opera Enerji Veri'!$C:$C, 'Opera Günlük Analiz'!$B14,'Opera Enerji Veri'!BY:BY) | AC14: =SUMIF('Opera Enerji Veri'!$C:$C, 'Opera Günlük Analiz'!$B14,'Opera Enerji Veri'!CI:CI) | AD14: =IFERROR(AC14/G14,0) | AE14: =J14+K14+L14+AB14-Y14 | AF14: =F14-AE14-Y14 | AG14: =Y14+AF14 | AH14: =IFERROR(AE14/G14,0) | AI14: =IF(G14=0,0,AG14/G14) | AJ14: =IFERROR(AI14/H14,0) | AK14: =IFERROR(ABS(Z14/G14),0) | AL14: =SUMIF('Opera Enerji Veri'!$C:$C, 'Opera Günlük Analiz'!$B14,'Opera Enerji Veri'!CH:CH) | AM14: =M14-Y14 | AN14: =IFERROR(AM14/M14,0) | AO14: =S14-AG14 | AP14: =IFERROR(AO14/S14,0)
B15: =B14+1 | C15: =IFERROR(AVERAGEIF('Opera Enerji Veri'!C:C,'Opera Günlük Analiz'!B15,'Opera Enerji Veri'!F:F),0) | D15: =IFERROR(AVERAGEIF('Opera Enerji Veri'!$C:$C,'Opera Günlük Analiz'!$B15,'Opera Enerji Veri'!G:G),0) | E15: =IFERROR(AVERAGEIF('Opera Enerji Veri'!$C:$C,'Opera Günlük Analiz'!$B15,'Opera Enerji Veri'!H:H),0) | F15: =SUMIF('Opera Enerji Veri'!$C:$C, 'Opera Günlük Analiz'!$B15,'Opera Enerji Veri'!BE:BE) | G15: =SUMIF('Opera Enerji Veri'!$C:$C, 'Opera Günlük Analiz'!$B15,'Opera Enerji Veri'!AY:AY) | H15: =IFERROR(F15/G15,0) | I15: =SUMIF('Opera Enerji Veri'!$C:$C, 'Opera Günlük Analiz'!$B15,'Opera Enerji Veri'!J:J) | J15: =SUMIF('Opera Enerji Veri'!$C:$C, 'Opera Günlük Analiz'!$B15,'Opera Enerji Veri'!BF:BF) | K15: =SUMIF('Opera Enerji Veri'!$C:$C, 'Opera Günlük Analiz'!$B15,'Opera Enerji Veri'!BG:BG) | L15: =SUMIF('Opera Enerji Veri'!$C:$C, 'Opera Günlük Analiz'!$B15,'Opera Enerji Veri'!BH:BH) | M15: =SUMIF('Opera Enerji Veri'!$C:$C, 'Opera Günlük Analiz'!$B15,'Opera Enerji Veri'!BB:BB) | N15: =SUMIF('Opera Enerji Veri'!$C:$C, 'Opera Günlük Analiz'!$B15,'Opera Enerji Veri'!BJ:BJ) | O15: =SUMIF('Opera Enerji Veri'!$C:$C, 'Opera Günlük Analiz'!$B15,'Opera Enerji Veri'!BK:BK) | P15: =SUMIF('Opera Enerji Veri'!$C:$C, 'Opera Günlük Analiz'!$B15,'Opera Enerji Veri'!BL:BL) | Q15: =J15+K15+P15-M15 | R15: =F15-Q15-M15 | S15: =M15+R15 | T15: =IFERROR(Q15/G15,0) | U15: =IF(G15=0,0,S15/G15) | V15: =IFERROR(U15/H15,0) | W15: =IFERROR(ABS(N15/G15),0) | X15: =SUMIF('Opera Enerji Veri'!$C:$C, 'Opera Günlük Analiz'!$B15,'Opera Enerji Veri'!BU:BU) | Y15: =SUMIF('Opera Enerji Veri'!$C:$C, 'Opera Günlük Analiz'!$B15,'Opera Enerji Veri'!BD:BD) | Z15: =SUMIF('Opera Enerji Veri'!$C:$C, 'Opera Günlük Analiz'!$B15,'Opera Enerji Veri'!BW:BW) | AA15: =SUMIF('Opera Enerji Veri'!$C:$C, 'Opera Günlük Analiz'!$B15,'Opera Enerji Veri'!BX:BX) | AB15: =SUMIF('Opera Enerji Veri'!$C:$C, 'Opera Günlük Analiz'!$B15,'Opera Enerji Veri'!BY:BY) | AC15: =SUMIF('Opera Enerji Veri'!$C:$C, 'Opera Günlük Analiz'!$B15,'Opera Enerji Veri'!CI:CI) | AD15: =IFERROR(AC15/G15,0) | AE15: =J15+K15+L15+AB15-Y15 | AF15: =F15-AE15-Y15 | AG15: =Y15+AF15 | AH15: =IFERROR(AE15/G15,0) | AI15: =IF(G15=0,0,AG15/G15) | AJ15: =IFERROR(AI15/H15,0) | AK15: =IFERROR(ABS(Z15/G15),0) | AL15: =SUMIF('Opera Enerji Veri'!$C:$C, 'Opera Günlük Analiz'!$B15,'Opera Enerji Veri'!CH:CH) | AM15: =M15-Y15 | AN15: =IFERROR(AM15/M15,0) | AO15: =S15-AG15 | AP15: =IFERROR(AO15/S15,0)
